<sdf version='1.7'>
  <world name='default'>
    <light name='sun' type='directional'>
      <cast_shadows>1</cast_shadows>
      <pose>0 0 10 0 -0 0</pose>
      <diffuse>0.8 0.8 0.8 1</diffuse>
      <specular>0.2 0.2 0.2 1</specular>
      <attenuation>
        <range>1000</range>
        <constant>0.9</constant>
        <linear>0.01</linear>
        <quadratic>0.001</quadratic>
      </attenuation>
      <direction>-0.5 0.1 -0.9</direction>
      <spot>
        <inner_angle>0</inner_angle>
        <outer_angle>0</outer_angle>
        <falloff>0</falloff>
      </spot>
    </light>
    <model name='ground_plane'>
      <static>1</static>
      <link name='link'>
        <collision name='collision'>
          <geometry>
            <plane>
              <normal>0 0 1</normal>
              <size>100 100</size>
            </plane>
          </geometry>
          <surface>
            <contact>
              <collide_bitmask>65535</collide_bitmask>
              <ode/>
            </contact>
            <friction>
              <ode>
                <mu>100</mu>
                <mu2>50</mu2>
              </ode>
              <torsional>
                <ode/>
              </torsional>
            </friction>
            <bounce/>
          </surface>
          <max_contacts>10</max_contacts>
        </collision>
        <visual name='visual'>
          <cast_shadows>0</cast_shadows>
          <geometry>
            <plane>
              <normal>0 0 1</normal>
              <size>100 100</size>
            </plane>
          </geometry>
          <material>
            <script>
              <uri>file://media/materials/scripts/gazebo.material</uri>
              <name>Gazebo/Grey</name>
            </script>
          </material>
        </visual>
        <self_collide>0</self_collide>
        <enable_wind>0</enable_wind>
        <kinematic>0</kinematic>
      </link>
    </model>
    <gravity>0 0 -9.8</gravity>
    <magnetic_field>6e-06 2.3e-05 -4.2e-05</magnetic_field>
    <atmosphere type='adiabatic'/>
    <physics type='ode'>
      <max_step_size>0.001</max_step_size>
      <real_time_factor>1</real_time_factor>
      <real_time_update_rate>1000</real_time_update_rate>
    </physics>
    <scene>
      <ambient>0.4 0.4 0.4 1</ambient>
      <background>0.7 0.7 0.7 1</background>
      <shadows>1</shadows>
    </scene>
    <audio>
      <device>default</device>
    </audio>
    <wind/>
    <spherical_coordinates>
      <surface_model>EARTH_WGS84</surface_model>
      <latitude_deg>0</latitude_deg>
      <longitude_deg>0</longitude_deg>
      <elevation>0</elevation>
      <heading_deg>0</heading_deg>
    </spherical_coordinates>
    <model name='OfficeChair'>
      <static>1</static>
      <link name='base_link'>
        <visual name='visual'>
          <geometry>
            <mesh>
              <uri>/home/pav/.ignition/fuel/fuel.ignitionrobotics.org/openrobotics/models/office chair/1/meshes/officechair.dae</uri>
            </mesh>
          </geometry>
          <material>
            <diffuse>1 1 1 1</diffuse>
            <specular>1 1 1 1</specular>
            <pbr>
              <metal>
                <albedo_map>materials/textures/OfficeChair_Albedo.png</albedo_map>
                <normal_map>materials/textures/OfficeChair_Normal.png</normal_map>
                <roughness_map>materials/textures/OfficeChair_Roughness.png</roughness_map>
                <metalness_map>materials/textures/OfficeChair_Metalness.png</metalness_map>
              </metal>
            </pbr>
          </material>
        </visual>
        <collision name='Box001'>
          <pose>0 0.03962 0.46685 0.087267 -0 0</pose>
          <geometry>
            <box>
              <size>0.511249 0.578359 0.108987</size>
            </box>
          </geometry>
          <max_contacts>10</max_contacts>
          <surface>
            <contact>
              <ode/>
            </contact>
            <bounce/>
            <friction>
              <torsional>
                <ode/>
              </torsional>
              <ode/>
            </friction>
          </surface>
        </collision>
        <collision name='Box002'>
          <pose>0 -0.200278 0.766385 -1.48353 0 0</pose>
          <geometry>
            <box>
              <size>0.511249 0.665113 0.108987</size>
            </box>
          </geometry>
          <max_contacts>10</max_contacts>
          <surface>
            <contact>
              <ode/>
            </contact>
            <bounce/>
            <friction>
              <torsional>
                <ode/>
              </torsional>
              <ode/>
            </friction>
          </surface>
        </collision>
        <collision name='Cylinder001'>
          <pose>0 0 0.239577 0 -0 0</pose>
          <geometry>
            <cylinder>
              <length>0.395591</length>
              <radius>0.0321281</radius>
            </cylinder>
          </geometry>
          <max_contacts>10</max_contacts>
          <surface>
            <contact>
              <ode/>
            </contact>
            <bounce/>
            <friction>
              <torsional>
                <ode/>
              </torsional>
              <ode/>
            </friction>
          </surface>
        </collision>
        <collision name='Cylinder002'>
          <pose>0.406934 -0.124695 0.037183 1.5708 -0 -0.067165</pose>
          <geometry>
            <cylinder>
              <length>0.0584031</length>
              <radius>0.0379998</radius>
            </cylinder>
          </geometry>
          <max_contacts>10</max_contacts>
          <surface>
            <contact>
              <ode/>
            </contact>
            <bounce/>
            <friction>
              <torsional>
                <ode/>
              </torsional>
              <ode/>
            </friction>
          </surface>
        </collision>
        <collision name='Cylinder003'>
          <pose>0.243918 0.348604 0.037183 1.5708 -0 1.17814</pose>
          <geometry>
            <cylinder>
              <length>0.0584031</length>
              <radius>0.0379998</radius>
            </cylinder>
          </geometry>
          <max_contacts>10</max_contacts>
          <surface>
            <contact>
              <ode/>
            </contact>
            <bounce/>
            <friction>
              <torsional>
                <ode/>
              </torsional>
              <ode/>
            </friction>
          </surface>
        </collision>
        <collision name='Cylinder004'>
          <pose>-0.255977 0.339873 0.037183 1.5708 0 2.44229</pose>
          <geometry>
            <cylinder>
              <length>0.0584031</length>
              <radius>0.0379998</radius>
            </cylinder>
          </geometry>
          <max_contacts>10</max_contacts>
          <surface>
            <contact>
              <ode/>
            </contact>
            <bounce/>
            <friction>
              <torsional>
                <ode/>
              </torsional>
              <ode/>
            </friction>
          </surface>
        </collision>
        <collision name='Cylinder005'>
          <pose>-0.40242 -0.13893 0.037183 1.5708 -0 -2.5742</pose>
          <geometry>
            <cylinder>
              <length>0.0584031</length>
              <radius>0.0379998</radius>
            </cylinder>
          </geometry>
          <max_contacts>10</max_contacts>
          <surface>
            <contact>
              <ode/>
            </contact>
            <bounce/>
            <friction>
              <torsional>
                <ode/>
              </torsional>
              <ode/>
            </friction>
          </surface>
        </collision>
        <collision name='Cylinder006'>
          <pose>0.007395 -0.425689 0.037183 1.5708 0 1.8213</pose>
          <geometry>
            <cylinder>
              <length>0.0584031</length>
              <radius>0.0379998</radius>
            </cylinder>
          </geometry>
          <max_contacts>10</max_contacts>
          <surface>
            <contact>
              <ode/>
            </contact>
            <bounce/>
            <friction>
              <torsional>
                <ode/>
              </torsional>
              <ode/>
            </friction>
          </surface>
        </collision>
        <collision name='Box003'>
          <pose>0 -0.208233 0.12911 0.069925 -0 0</pose>
          <geometry>
            <box>
              <size>0.050443 0.404478 0.059061</size>
            </box>
          </geometry>
          <max_contacts>10</max_contacts>
          <surface>
            <contact>
              <ode/>
            </contact>
            <bounce/>
            <friction>
              <torsional>
                <ode/>
              </torsional>
              <ode/>
            </friction>
          </surface>
        </collision>
        <collision name='Box004'>
          <pose>-0.198041 -0.064348 0.12911 0.069925 0 -1.25664</pose>
          <geometry>
            <box>
              <size>0.050443 0.404478 0.059061</size>
            </box>
          </geometry>
          <max_contacts>10</max_contacts>
          <surface>
            <contact>
              <ode/>
            </contact>
            <bounce/>
            <friction>
              <torsional>
                <ode/>
              </torsional>
              <ode/>
            </friction>
          </surface>
        </collision>
        <collision name='Box005'>
          <pose>-0.122396 0.168464 0.12911 0.069925 -0 -2.51327</pose>
          <geometry>
            <box>
              <size>0.050443 0.404478 0.059061</size>
            </box>
          </geometry>
          <max_contacts>10</max_contacts>
          <surface>
            <contact>
              <ode/>
            </contact>
            <bounce/>
            <friction>
              <torsional>
                <ode/>
              </torsional>
              <ode/>
            </friction>
          </surface>
        </collision>
        <collision name='Box006'>
          <pose>0.122396 0.168464 0.12911 0.069925 0 2.51327</pose>
          <geometry>
            <box>
              <size>0.050443 0.404478 0.059061</size>
            </box>
          </geometry>
          <max_contacts>10</max_contacts>
          <surface>
            <contact>
              <ode/>
            </contact>
            <bounce/>
            <friction>
              <torsional>
                <ode/>
              </torsional>
              <ode/>
            </friction>
          </surface>
        </collision>
        <collision name='Box007'>
          <pose>0.198041 -0.064348 0.12911 0.069925 -0 1.25664</pose>
          <geometry>
            <box>
              <size>0.050443 0.404478 0.059061</size>
            </box>
          </geometry>
          <max_contacts>10</max_contacts>
          <surface>
            <contact>
              <ode/>
            </contact>
            <bounce/>
            <friction>
              <torsional>
                <ode/>
              </torsional>
              <ode/>
            </friction>
          </surface>
        </collision>
        <collision name='Box008'>
          <pose>-0.275812 -0.002621 0.741555 1.5708 0.139626 -1.5708</pose>
          <geometry>
            <box>
              <size>0.26452 0.043899 0.065929</size>
            </box>
          </geometry>
          <max_contacts>10</max_contacts>
          <surface>
            <contact>
              <ode/>
            </contact>
            <bounce/>
            <friction>
              <torsional>
                <ode/>
              </torsional>
              <ode/>
            </friction>
          </surface>
        </collision>
        <collision name='Box009'>
          <pose>-0.273179 -0.018006 0.599892 1.5708 0.139626 -1.5708</pose>
          <geometry>
            <box>
              <size>0.06613 0.280955 0.03692</size>
            </box>
          </geometry>
          <max_contacts>10</max_contacts>
          <surface>
            <contact>
              <ode/>
            </contact>
            <bounce/>
            <friction>
              <torsional>
                <ode/>
              </torsional>
              <ode/>
            </friction>
          </surface>
        </collision>
        <collision name='Box010'>
          <pose>0.275965 -0.002621 0.741555 1.5708 -0.139626 1.5708</pose>
          <geometry>
            <box>
              <size>0.26452 0.043899 0.065929</size>
            </box>
          </geometry>
          <max_contacts>10</max_contacts>
          <surface>
            <contact>
              <ode/>
            </contact>
            <bounce/>
            <friction>
              <torsional>
                <ode/>
              </torsional>
              <ode/>
            </friction>
          </surface>
        </collision>
        <collision name='Box011'>
          <pose>0.27346 -0.018006 0.599892 1.5708 -0.139626 1.5708</pose>
          <geometry>
            <box>
              <size>0.06613 0.280955 0.03692</size>
            </box>
          </geometry>
          <max_contacts>10</max_contacts>
          <surface>
            <contact>
              <ode/>
            </contact>
            <bounce/>
            <friction>
              <torsional>
                <ode/>
              </torsional>
              <ode/>
            </friction>
          </surface>
        </collision>
        <self_collide>0</self_collide>
        <enable_wind>0</enable_wind>
        <kinematic>0</kinematic>
      </link>
      <pose>1.20581 1.28572 0 0 -0 0</pose>
    </model>
    <model name='HospitalBot'>
      <link name='body'>
        <pose>0 0 0 0 -0 0</pose>
        <inertial>
          <pose>0 0 0.693 0 -0 0</pose>
          <mass>170</mass>
          <inertia>
            <ixx>34.6605</ixx>
            <iyy>32.8369</iyy>
            <izz>13.0691</izz>
            <ixy>0</ixy>
            <ixz>0</ixz>
            <iyz>0</iyz>
          </inertia>
        </inertial>
        <collision name='collision'>
          <pose>0 0 0.7 0 -0 0</pose>
          <geometry>
            <box>
              <size>0.7 0.7 1.4</size>
            </box>
          </geometry>
          <surface>
            <friction>
              <torsional>
                <coefficient>0</coefficient>
                <ode/>
              </torsional>
              <ode>
                <mu>0</mu>
                <mu2>0</mu2>
              </ode>
              <bullet>
                <friction>0</friction>
                <friction2>0</friction2>
                <rolling_friction>0</rolling_friction>
              </bullet>
            </friction>
            <contact>
              <ode/>
            </contact>
            <bounce/>
          </surface>
          <max_contacts>10</max_contacts>
        </collision>
        <visual name='visual'>
          <geometry>
            <mesh>
              <uri>https://fuel.ignitionrobotics.org/1.0/openrobotics/models/hospitalbot/2/files/meshes/HospitalBot.obj</uri>
            </mesh>
          </geometry>
        </visual>
        <visual name='front_wheel_left'>
          <pose>0.17 -0.21 0.03 0 -0 0</pose>
          <geometry>
            <mesh>
              <uri>https://fuel.ignitionrobotics.org/1.0/openrobotics/models/hospitalbot/2/files/meshes/SmallWheel.obj</uri>
            </mesh>
          </geometry>
        </visual>
        <visual name='back_wheel_left'>
          <pose>-0.24 -0.21 0.03 0 -0 0</pose>
          <geometry>
            <mesh>
              <uri>https://fuel.ignitionrobotics.org/1.0/openrobotics/models/hospitalbot/2/files/meshes/SmallWheel.obj</uri>
            </mesh>
          </geometry>
        </visual>
        <visual name='front_wheel_right'>
          <pose>0.17 0.21 0.03 0 -0 0</pose>
          <geometry>
            <mesh>
              <uri>https://fuel.ignitionrobotics.org/1.0/openrobotics/models/hospitalbot/2/files/meshes/SmallWheel.obj</uri>
            </mesh>
          </geometry>
        </visual>
        <visual name='back_wheel_right'>
          <pose>-0.24 0.21 0.03 0 -0 0</pose>
          <geometry>
            <mesh>
              <uri>https://fuel.ignitionrobotics.org/1.0/openrobotics/models/hospitalbot/2/files/meshes/SmallWheel.obj</uri>
            </mesh>
          </geometry>
        </visual>
        <self_collide>0</self_collide>
        <enable_wind>0</enable_wind>
        <kinematic>0</kinematic>
      </link>
      <link name='suspension_tire_left'>
        <pose>0 0.21 0.06 0 -0 0</pose>
        <inertial>
          <mass>1</mass>
          <inertia>
            <ixx>1</ixx>
            <iyy>1</iyy>
            <izz>1</izz>
            <ixy>0</ixy>
            <ixz>0</ixz>
            <iyz>0</iyz>
          </inertia>
          <pose>0 0 0 0 -0 0</pose>
        </inertial>
        <self_collide>0</self_collide>
        <enable_wind>0</enable_wind>
        <kinematic>0</kinematic>
      </link>
      <joint name='joint_suspension_tire_left' type='prismatic'>
        <parent>body</parent>
        <child>suspension_tire_left</child>
        <axis>
          <xyz>0 0 1</xyz>
          <dynamics>
            <damping>500</damping>
            <spring_reference>-0.05</spring_reference>
            <spring_stiffness>2000</spring_stiffness>
          </dynamics>
          <limit>
            <lower>-1e+16</lower>
            <upper>1e+16</upper>
          </limit>
        </axis>
        <physics>
          <ode>
            <implicit_spring_damper>1</implicit_spring_damper>
            <limit>
              <cfm>0</cfm>
              <erp>0.2</erp>
            </limit>
          </ode>
        </physics>
      </joint>
      <link name='tire_left'>
        <pose>0 0.21 0.06 0 -0 0</pose>
        <inertial>
          <pose>0 0 0 0 -0 0</pose>
          <mass>5</mass>
          <inertia>
            <ixx>0.757897</ixx>
            <iyy>1.30298</iyy>
            <izz>0.757897</izz>
            <ixy>0</ixy>
            <ixz>0</ixz>
            <iyz>0</iyz>
          </inertia>
        </inertial>
        <visual name='fat_wheel_left'>
          <geometry>
            <mesh>
              <uri>https://fuel.ignitionrobotics.org/1.0/openrobotics/models/hospitalbot/2/files/meshes/FatWheel.obj</uri>
            </mesh>
          </geometry>
        </visual>
        <collision name='tire_left'>
          <geometry>
            <sphere>
              <radius>0.06137</radius>
            </sphere>
          </geometry>
          <surface>
            <contact>
              <ode>
                <kp>1e+07</kp>
                <kd>1</kd>
              </ode>
            </contact>
            <bounce/>
            <friction>
              <torsional>
                <ode/>
              </torsional>
              <ode/>
            </friction>
          </surface>
          <max_contacts>10</max_contacts>
        </collision>
        <self_collide>0</self_collide>
        <enable_wind>0</enable_wind>
        <kinematic>0</kinematic>
      </link>
      <joint name='joint_tire_left' type='revolute'>
        <parent>suspension_tire_left</parent>
        <child>tire_left</child>
        <axis>
          <xyz>0 1 0</xyz>
          <limit>
            <lower>-1e+16</lower>
            <upper>1e+16</upper>
          </limit>
          <dynamics>
            <spring_reference>0</spring_reference>
            <spring_stiffness>0</spring_stiffness>
          </dynamics>
        </axis>
      </joint>
      <link name='suspension_tire_right'>
        <pose>0 -0.21 0.06 0 -0 0</pose>
        <inertial>
          <mass>1</mass>
          <inertia>
            <ixx>1</ixx>
            <iyy>1</iyy>
            <izz>1</izz>
            <ixy>0</ixy>
            <ixz>0</ixz>
            <iyz>0</iyz>
          </inertia>
          <pose>0 0 0 0 -0 0</pose>
        </inertial>
        <self_collide>0</self_collide>
        <enable_wind>0</enable_wind>
        <kinematic>0</kinematic>
      </link>
      <joint name='joint_suspension_tire_right' type='prismatic'>
        <parent>body</parent>
        <child>suspension_tire_right</child>
        <axis>
          <xyz>0 0 1</xyz>
          <dynamics>
            <damping>500</damping>
            <spring_reference>-0.05</spring_reference>
            <spring_stiffness>2000</spring_stiffness>
          </dynamics>
          <limit>
            <lower>-1e+16</lower>
            <upper>1e+16</upper>
          </limit>
        </axis>
        <physics>
          <ode>
            <implicit_spring_damper>1</implicit_spring_damper>
            <limit>
              <cfm>0</cfm>
              <erp>0.2</erp>
            </limit>
          </ode>
        </physics>
      </joint>
      <link name='tire_right'>
        <pose>0 -0.21 0.06 0 -0 0</pose>
        <inertial>
          <pose>0 0 0 0 -0 0</pose>
          <mass>5</mass>
          <inertia>
            <ixx>0.757897</ixx>
            <iyy>1.30298</iyy>
            <izz>0.757897</izz>
            <ixy>0</ixy>
            <ixz>0</ixz>
            <iyz>0</iyz>
          </inertia>
        </inertial>
        <visual name='fat_wheel_right'>
          <geometry>
            <mesh>
              <uri>https://fuel.ignitionrobotics.org/1.0/openrobotics/models/hospitalbot/2/files/meshes/FatWheel.obj</uri>
            </mesh>
          </geometry>
        </visual>
        <collision name='tire_right'>
          <geometry>
            <sphere>
              <radius>0.06137</radius>
            </sphere>
          </geometry>
          <surface>
            <contact>
              <ode>
                <kp>1e+07</kp>
                <kd>1</kd>
              </ode>
            </contact>
            <bounce/>
            <friction>
              <torsional>
                <ode/>
              </torsional>
              <ode/>
            </friction>
          </surface>
          <max_contacts>10</max_contacts>
        </collision>
        <self_collide>0</self_collide>
        <enable_wind>0</enable_wind>
        <kinematic>0</kinematic>
      </link>
      <joint name='joint_tire_right' type='revolute'>
        <parent>suspension_tire_right</parent>
        <child>tire_right</child>
        <axis>
          <xyz>0 1 0</xyz>
          <limit>
            <lower>-1e+16</lower>
            <upper>1e+16</upper>
          </limit>
          <dynamics>
            <spring_reference>0</spring_reference>
            <spring_stiffness>0</spring_stiffness>
          </dynamics>
        </axis>
      </joint>
      <pose>0.481008 -1.76491 0 0 -0 0</pose>
    </model>
    <state world_name='default'>
      <sim_time>706 784000000</sim_time>
      <real_time>1430 66238602</real_time>
      <wall_time>1706571777 156088548</wall_time>
      <iterations>706784</iterations>
      <model name='HospitalBot'>
        <pose>0.481009 -1.76491 -0 0 -0 1e-06</pose>
        <scale>1 1 1</scale>
        <link name='body'>
          <pose>0.481009 -1.76491 -0 0 -0 1e-06</pose>
          <velocity>1.6e-05 2e-05 0 -4e-06 4e-06 0</velocity>
          <acceleration>0.034688 0.050503 1e-06 -0.00861 0.008619 0.000578</acceleration>
          <wrench>5.89698 8.58559 0.000173 0 -0 0</wrench>
        </link>
        <link name='suspension_tire_left'>
          <pose>0.481009 -1.55491 0.06135 0 -0 1e-06</pose>
          <velocity>1e-06 7e-06 -0.005702 -1e-05 9e-06 1e-06</velocity>
          <acceleration>0.002409 0.014387 -6.6e-05 -0.02018 0.017015 0.002798</acceleration>
          <wrench>0.002409 0.014387 -6.6e-05 0 -0 0</wrench>
        </link>
        <link name='suspension_tire_right'>
          <pose>0.481009 -1.97491 0.06135 0 -0 1e-06</pose>
          <velocity>1.9e-05 2.4e-05 -0.005702 -8e-06 9e-06 -1e-06</velocity>
          <acceleration>0.034445 0.051362 5.8e-05 -0.017244 0.016577 -0.002176</acceleration>
          <wrench>0.034445 0.051362 5.8e-05 0 -0 0</wrench>
        </link>
        <link name='tire_left'>
          <pose>0.481009 -1.55491 0.06135 0 -6e-06 1e-06</pose>
          <velocity>-4e-06 1e-06 -0.005702 -1.3e-05 -7.3e-05 1e-06</velocity>
          <acceleration>-0.008116 0.001992 -6.5e-05 -0.027978 -0.13611 0.002783</acceleration>
          <wrench>-0.040578 0.00996 -0.000327 0 -0 0</wrench>
        </link>
        <link name='tire_right'>
          <pose>0.481009 -1.97491 0.06135 0 -1e-06 1e-06</pose>
          <velocity>-4e-06 1e-06 -0.005702 -1.3e-05 -7.5e-05 -1e-06</velocity>
          <acceleration>-0.008315 0.001988 6.2e-05 -0.02778 -0.139502 -0.002209</acceleration>
          <wrench>-0.041577 0.009939 0.000311 0 -0 0</wrench>
        </link>
      </model>
      <model name='OfficeChair'>
        <pose>1.20581 1.28572 0 0 -0 0</pose>
        <scale>1 1 1</scale>
        <link name='base_link'>
          <pose>1.20581 1.28572 0 0 -0 0</pose>
          <velocity>0 0 0 0 -0 0</velocity>
          <acceleration>0 0 0 0 -0 0</acceleration>
          <wrench>0 0 0 0 -0 0</wrench>
        </link>
      </model>
      <model name='ground_plane'>
        <pose>0 0 0 0 -0 0</pose>
        <scale>1 1 1</scale>
        <link name='link'>
          <pose>0 0 0 0 -0 0</pose>
          <velocity>0 0 0 0 -0 0</velocity>
          <acceleration>0 0 0 0 -0 0</acceleration>
          <wrench>0 0 0 0 -0 0</wrench>
        </link>
      </model>
      <light name='sun'>
        <pose>0 0 10 0 -0 0</pose>
      </light>
    </state>
    <gui fullscreen='0'>
      <camera name='user_camera'>
        <pose>5.58852 -4.18142 2.3631 -0 0.439643 2.3402</pose>
        <view_controller>orbit</view_controller>
        <projection_type>perspective</projection_type>
      </camera>
    </gui>
  </world>
</sdf>
